<?xml version="1.0"?>
<robot xmlns:xacro="http://ros.org/wiki/xacro">

  <xacro:include filename="$(find jaka_robot)/urdf/jaka.transmission.xacro" />

  <xacro:macro name="zu7_robot" params="prefix">

    <link name="${prefix}base_link">
        <visual>
        <origin
            xyz="0 0 0"
            rpy="0 0 0" />
        <geometry>
            <mesh
            filename="package://jaka_robot/meshes/base.DAE" />
        </geometry>
        </visual>
        <collision>
        <origin
            xyz="0 0 0"
            rpy="0 0 0" />
        <geometry>
            <mesh
            filename="package://jaka_robot/meshes/base.STL" />
        </geometry>
        </collision>
    </link>
    
    <link name="${prefix}shoulder_link">
        <visual>
        <origin
            xyz="0 0 0"
            rpy="0 0 0" />
        <geometry>
            <mesh
            filename="package://jaka_robot/meshes/shoulder_link.DAE" />
        </geometry>
        </visual>
        <collision>
        <origin
            xyz="0 0 0"
            rpy="0 0 0" />
        <geometry>
            <mesh
            filename="package://jaka_robot/meshes/shoulder_link.STL" />
        </geometry>
        </collision>
    </link>
    
    <joint name="${prefix}shoulder_pan_joint" type="revolute">
        <origin
        xyz="0 0 0.12015"
        rpy="0 0 0" />
        <parent
        link="${prefix}base_link" />
        <child
        link="${prefix}shoulder_link" />
        <axis
        xyz="0 0 1" />
        <limit
        lower="${-2*pi}"
        upper="${2*pi}"
        effort="0"
        velocity="${pi}" />
    </joint>

    <link name="${prefix}upper_arm_link">
        <visual>
        <origin
            xyz="0 0 0"
            rpy="0 0 0" />
        <geometry>
            <mesh
            filename="package://jaka_robot/meshes/upper_arm_link.DAE" />
        </geometry>
        </visual>
        <collision>
        <origin
            xyz="0 0 0"
            rpy="0 0 0" />
        <geometry>
            <mesh
            filename="package://jaka_robot/meshes/upper_arm_link.STL" />
        </geometry>
        </collision>
    </link>

    <joint name="${prefix}shoulder_lift_joint" type="revolute">
        <origin
        xyz="0 0.14415 0"
        rpy="${-pi/2} 0 0" />
        <parent
        link="${prefix}shoulder_link" />
        <child
        link="${prefix}upper_arm_link" />
        <axis
        xyz="0 0 -1" />
        <limit
        lower="-1.4835"
        upper="4.625"
        effort="0"
        velocity="${pi}" />
    </joint>

    <link name="${prefix}forearm_link">
        <visual>
        <origin
            xyz="0 0 0"
            rpy="0 0 0" />
        <geometry>
            <mesh
            filename="package://jaka_robot/meshes/forearm_link.DAE" />
        </geometry>
        </visual>
        <collision>
        <origin
            xyz="0 0 0"
            rpy="0 0 0" />
        <geometry>
            <mesh
            filename="package://jaka_robot/meshes/forearm_link.STL" />
        </geometry>
        </collision>
    </link>

    <joint name="${prefix}elbow_joint" type="revolute">
        <origin
        xyz="0.36 0 -0.14264"
        rpy="0 0 0" />
        <parent
        link="${prefix}upper_arm_link" />
        <child
        link="${prefix}forearm_link" />
        <axis
        xyz="0 0 -1" />
        <limit
        lower="-3.05"
        upper="3.05"
        effort="0"
        velocity="${pi}" />
    </joint>

    <link name="${prefix}wrist_1_link">
        <visual>
        <origin
            xyz="0 0 0"
            rpy="0 0 0" />
        <geometry>
            <mesh
            filename="package://jaka_robot/meshes/wrist_1_link.DAE" />
        </geometry>
        </visual>
        <collision>
        <origin
            xyz="0 0 0"
            rpy="0 0 0" />
        <geometry>
            <mesh
            filename="package://jaka_robot/meshes/wrist_1_link.STL" />
        </geometry>
        </collision>
    </link>

    <joint name="${prefix}wrist_1_joint" type="revolute">
        <origin
        xyz="0.3035 0 0.1135"
        rpy="0 0 0" />
        <parent
        link="${prefix}forearm_link" />
        <child
        link="${prefix}wrist_1_link" />
        <axis
        xyz="0 0 -1" />
        <limit
        lower="-1.4835"
        upper="4.625"
        effort="0"
        velocity="${pi}" />
    </joint>

    <link name="${prefix}wrist_2_link">
        <visual>
        <origin
            xyz="0 0 0"
            rpy="0 0 0" />
        <geometry>
            <mesh
            filename="package://jaka_robot/meshes/wrist_2_link.DAE" />
        </geometry>
        </visual>
        <collision>
        <origin
            xyz="0 0 0"
            rpy="0 0 0" />
        <geometry>
            <mesh
            filename="package://jaka_robot/meshes/wrist_2_link.STL" />
        </geometry>
        </collision>
    </link>

    <joint name="${prefix}wrist_2_joint" type="revolute">
        <origin
        xyz="0 0.1135 0"
        rpy="${-pi/2} 0 0" />
        <parent
        link="${prefix}wrist_1_link" />
        <child
        link="${prefix}wrist_2_link" />
        <axis
        xyz="0 0 1" />
        <limit
        lower="${-2*pi}"
        upper="${2*pi}"
        effort="0"
        velocity="${pi}" />
    </joint>

    <link name="${prefix}wrist_3_link">
        <visual>
        <origin
            xyz="0 0 0"
            rpy="0 0 0" />
        <geometry>
            <mesh
            filename="package://jaka_robot/meshes/wrist_3_link.DAE" />
        </geometry>
        </visual>
        <collision>
        <origin
            xyz="0 0 0"
            rpy="0 0 0" />
        <geometry>
            <mesh
            filename="package://jaka_robot/meshes/wrist_3_link.STL" />
        </geometry>
        </collision>
    </link>

    <joint name="${prefix}wrist_3_joint" type="revolute">
        <origin
        xyz="0 0.107 0"
        rpy="${-pi/2} 0 0" />
        <parent
        link="${prefix}wrist_2_link" />
        <child
        link="${prefix}wrist_3_link" />
        <axis
        xyz="0 0 1" />
        <limit
        lower="${-2*pi}"
        upper="${2*pi}"
        effort="0"
        velocity="${pi}" />
    </joint>

    <joint name="${prefix}ee_fixed_joint" type="fixed">
      <parent link="${prefix}wrist_3_link" />
      <child link = "${prefix}ee_link" />
      <origin xyz="0.0 0.0 0.0" rpy="${pi/2.0} ${-pi/2.0} 0.0" />
    </joint>

    <link name="${prefix}ee_link"/>

    <xacro:jaka_arm_transmission prefix="${prefix}" />

    <link name="${prefix}tool0"/>
    <joint name="${prefix}wrist_3_link-tool0_fixed_joint" type="fixed">
      <origin xyz="0 0 0" rpy="0 0 0"/>
      <parent link="${prefix}wrist_3_link"/>
      <child link="${prefix}tool0"/>
    </joint>

  </xacro:macro>
</robot>
